Traceback (most recent call last):
  File "c:\python39\lib\site-packages\jupyter_cache\executors\utils.py", line 51, in single_nb_execution
    executenb(
  File "c:\python39\lib\site-packages\nbclient\client.py", line 1112, in execute
    return NotebookClient(nb=nb, resources=resources, km=km, **kwargs).execute()
  File "c:\python39\lib\site-packages\nbclient\util.py", line 74, in wrapped
    return just_run(coro(*args, **kwargs))
  File "c:\python39\lib\site-packages\nbclient\util.py", line 53, in just_run
    return loop.run_until_complete(coro)
  File "c:\python39\lib\asyncio\base_events.py", line 642, in run_until_complete
    return future.result()
  File "c:\python39\lib\site-packages\nbclient\client.py", line 553, in async_execute
    await self.async_execute_cell(
  File "c:\python39\lib\site-packages\nbclient\client.py", line 857, in async_execute_cell
    self._check_raise_for_error(cell, exec_reply)
  File "c:\python39\lib\site-packages\nbclient\client.py", line 760, in _check_raise_for_error
    raise CellExecutionError.from_cell_and_msg(cell, exec_reply_content)
nbclient.exceptions.CellExecutionError: An error occurred while executing the following cell:
------------------
x[sel]
------------------

[1;31m---------------------------------------------------------------------------[0m
[1;31mTypeError[0m                                 Traceback (most recent call last)
[1;32m~\AppData\Local\Temp/ipykernel_38224/1928943738.py[0m in [0;36m<module>[1;34m[0m
[1;32m----> 1[1;33m [0mx[0m[1;33m[[0m[0msel[0m[1;33m][0m[1;33m[0m[1;33m[0m[0m
[0m
[1;31mTypeError[0m: 'Add' object is not subscriptable
TypeError: 'Add' object is not subscriptable

