Traceback (most recent call last):
  File "C:\Users\janko\AppData\Local\Programs\Python\Python310\lib\site-packages\jupyter_cache\executors\utils.py", line 51, in single_nb_execution
    executenb(
  File "C:\Users\janko\AppData\Local\Programs\Python\Python310\lib\site-packages\nbclient\client.py", line 1204, in execute
    return NotebookClient(nb=nb, resources=resources, km=km, **kwargs).execute()
  File "C:\Users\janko\AppData\Local\Programs\Python\Python310\lib\site-packages\nbclient\util.py", line 84, in wrapped
    return just_run(coro(*args, **kwargs))
  File "C:\Users\janko\AppData\Local\Programs\Python\Python310\lib\site-packages\nbclient\util.py", line 62, in just_run
    return loop.run_until_complete(coro)
  File "C:\Users\janko\AppData\Local\Programs\Python\Python310\lib\asyncio\base_events.py", line 646, in run_until_complete
    return future.result()
  File "C:\Users\janko\AppData\Local\Programs\Python\Python310\lib\site-packages\nbclient\client.py", line 663, in async_execute
    await self.async_execute_cell(
  File "C:\Users\janko\AppData\Local\Programs\Python\Python310\lib\site-packages\nbclient\client.py", line 965, in async_execute_cell
    await self._check_raise_for_error(cell, cell_index, exec_reply)
  File "C:\Users\janko\AppData\Local\Programs\Python\Python310\lib\site-packages\nbclient\client.py", line 862, in _check_raise_for_error
    raise CellExecutionError.from_cell_and_msg(cell, exec_reply_content)
nbclient.exceptions.CellExecutionError: An error occurred while executing the following cell:
------------------
import sympy as sym
t, Ï‰_0, Ï‰_d, d_x_0, Î´= sym.symbols('t, \omega_0, \omega_d, d_x_0, \delta', real=True)
podatki = {Ï‰_0: 1, d_x_0: 1, Î´: 0.1}

Ï‰_d = Ï‰_0 * sym.sqrt(1-Î´**2)

ovojnica = d_x_0/Ï‰_d * sym.exp(-Î´*Ï‰_0*t)

x = ovojnica * sym.sin(Ï‰_d*t)

p1 = sym.plot(ovojnica.subs(podatki), (t,0,50), line_color='C0', xlabel='$t$ [s]', ylabel='$x_h(t)$', title='ÄŒasovna domena',
             label='Ovojnica', show=False)
p2 = sym.plot(x.subs(podatki), (t,0,50), line_color='C1', 
             label='$x_h(t)$', show=False)
p1.extend(p2)
p1.legend = True
p1.show()
------------------

[1;31m---------------------------------------------------------------------------[0m
[1;31mModuleNotFoundError[0m                       Traceback (most recent call last)
Input [1;32mIn [1][0m, in [0;36m<cell line: 1>[1;34m()[0m
[1;32m----> 1[0m [38;5;28;01mimport[39;00m [38;5;21;01msympy[39;00m [38;5;28;01mas[39;00m [38;5;21;01msym[39;00m
[0;32m      2[0m t, Ï‰_0, Ï‰_d, d_x_0, Î´[38;5;241m=[39m sym[38;5;241m.[39msymbols([38;5;124m'[39m[38;5;124mt, [39m[38;5;124m\[39m[38;5;124momega_0, [39m[38;5;124m\[39m[38;5;124momega_d, d_x_0, [39m[38;5;124m\[39m[38;5;124mdelta[39m[38;5;124m'[39m, real[38;5;241m=[39m[38;5;28;01mTrue[39;00m)
[0;32m      3[0m podatki [38;5;241m=[39m {Ï‰_0: [38;5;241m1[39m, d_x_0: [38;5;241m1[39m, Î´: [38;5;241m0.1[39m}

[1;31mModuleNotFoundError[0m: No module named 'sympy'
ModuleNotFoundError: No module named 'sympy'

