Traceback (most recent call last):
  File "c:\python39\lib\site-packages\jupyter_cache\executors\utils.py", line 51, in single_nb_execution
    executenb(
  File "c:\python39\lib\site-packages\nbclient\client.py", line 1112, in execute
    return NotebookClient(nb=nb, resources=resources, km=km, **kwargs).execute()
  File "c:\python39\lib\site-packages\nbclient\util.py", line 74, in wrapped
    return just_run(coro(*args, **kwargs))
  File "c:\python39\lib\site-packages\nbclient\util.py", line 53, in just_run
    return loop.run_until_complete(coro)
  File "c:\python39\lib\asyncio\base_events.py", line 642, in run_until_complete
    return future.result()
  File "c:\python39\lib\site-packages\nbclient\client.py", line 553, in async_execute
    await self.async_execute_cell(
  File "c:\python39\lib\site-packages\nbclient\client.py", line 857, in async_execute_cell
    self._check_raise_for_error(cell, exec_reply)
  File "c:\python39\lib\site-packages\nbclient\client.py", line 760, in _check_raise_for_error
    raise CellExecutionError.from_cell_and_msg(cell, exec_reply_content)
nbclient.exceptions.CellExecutionError: An error occurred while executing the following cell:
------------------
import sympy as sym
t, Ï‰_0, Ï‰_d, d_x_0, Î´, A, B, Ï„ = sym.symbols('t, \omega_0, \omega_d, d_x_0, \delta, A, B, \\tau', real=True)
Ï€ = sym.pi
podatki = {Ï‰_0: 1, d_x_0: 1, Î´: 0.1, A: .5, B: 10}

Ï‰_d = Ï‰_0 * sym.sqrt(1-Î´**2)
ovojnica = d_x_0/Ï‰_d * sym.exp(-Î´*Ï‰_0*t)
h = ovojnica * sym.sin(Ï‰_d*t)*sym.Heaviside(t)

f = A*t*(sym.Heaviside(t)-sym.Heaviside(t-B))

fh = (f.subs(t, Ï„)*h.subs(t, t-Ï„)).subs(podatki)
fh = sym.integrate(fh, (Ï„, 0, t))

p1 = sym.plot(h.subs(podatki), (t,-5,50), line_color='C0', xlabel='$t$ [s]', ylabel='', title='ÄŒasovna domena',
             label='$h(t)$', show=False)
p2 = sym.plot(f.subs(podatki), (t,-5,50), line_color='C1', 
             label='$f(t)$', show=False)
p3 = sym.plot(X, (t,-5,50), line_color='C2', 
             label='$f(t)*h(t)$', show=False)
p1.extend(p2)
p1.extend(p3)
p1.legend = True
p1.show()
------------------

[1;31m---------------------------------------------------------------------------[0m
[1;31mNameError[0m                                 Traceback (most recent call last)
[1;32m~\AppData\Local\Temp/ipykernel_80872/4189941778.py[0m in [0;36m<module>[1;34m[0m
[0;32m     17[0m p2 = sym.plot(f.subs(podatki), (t,-5,50), line_color='C1', 
[0;32m     18[0m              label='$f(t)$', show=False)
[1;32m---> 19[1;33m p3 = sym.plot(X, (t,-5,50), line_color='C2', 
[0m[0;32m     20[0m              label='$f(t)*h(t)$', show=False)
[0;32m     21[0m [0mp1[0m[1;33m.[0m[0mextend[0m[1;33m([0m[0mp2[0m[1;33m)[0m[1;33m[0m[1;33m[0m[0m

[1;31mNameError[0m: name 'X' is not defined
NameError: name 'X' is not defined

